{"timestamp":"2025-10-24T13:47:05.840360Z","level":"info","event":"DAG bundles loaded: dags-folder, example_dags","logger":"airflow.dag_processing.bundles.manager.DagBundlesManager","filename":"manager.py","lineno":179}
{"timestamp":"2025-10-24T13:47:05.850629Z","level":"info","event":"Filling up the DagBag from /opt/airflow/dags/coresentiment_V2.py","logger":"airflow.models.dagbag.DagBag","filename":"dagbag.py","lineno":593}
{"timestamp":"2025-10-24T13:47:19.380206Z","level":"info","event":"Task instance is in running state","logger":"task.stdout"}
{"timestamp":"2025-10-24T13:47:19.414479Z","level":"info","event":" Previous state of the Task instance: TaskInstanceState.QUEUED","logger":"task.stdout"}
{"timestamp":"2025-10-24T13:47:19.417375Z","level":"info","event":"Current task name:get_top_company","logger":"task.stdout"}
{"timestamp":"2025-10-24T13:47:19.421241Z","level":"info","event":"Dag name:core-sentiment-V2","logger":"task.stdout"}
{"timestamp":"2025-10-24T13:47:19.860474Z","level":"error","event":"Task failed with exception","logger":"task","filename":"task_runner.py","lineno":994,"error_detail":[{"exc_type":"TypeError","exc_value":"dict is not a sequence","exc_notes":[],"syntax_error":null,"is_cause":false,"frames":[{"filename":"/home/airflow/.local/lib/python3.12/site-packages/airflow/sdk/execution_time/task_runner.py","lineno":920,"name":"run"},{"filename":"/home/airflow/.local/lib/python3.12/site-packages/airflow/sdk/execution_time/task_runner.py","lineno":1307,"name":"_execute_task"},{"filename":"/home/airflow/.local/lib/python3.12/site-packages/airflow/sdk/bases/operator.py","lineno":416,"name":"wrapper"},{"filename":"/home/airflow/.local/lib/python3.12/site-packages/airflow/providers/standard/operators/python.py","lineno":216,"name":"execute"},{"filename":"/home/airflow/.local/lib/python3.12/site-packages/airflow/providers/standard/operators/python.py","lineno":239,"name":"execute_callable"},{"filename":"/home/airflow/.local/lib/python3.12/site-packages/airflow/sdk/execution_time/callback_runner.py","lineno":82,"name":"run"},{"filename":"/opt/airflow/dags/coresentiment_V2.py","lineno":133,"name":"_get_top_company"},{"filename":"/home/airflow/.local/lib/python3.12/site-packages/pandas/io/sql.py","lineno":486,"name":"read_sql_query"},{"filename":"/home/airflow/.local/lib/python3.12/site-packages/pandas/io/sql.py","lineno":1776,"name":"read_query"},{"filename":"/home/airflow/.local/lib/python3.12/site-packages/pandas/io/sql.py","lineno":1599,"name":"execute"},{"filename":"/home/airflow/.local/lib/python3.12/site-packages/sqlalchemy/engine/base.py","lineno":1770,"name":"exec_driver_sql"},{"filename":"/home/airflow/.local/lib/python3.12/site-packages/sqlalchemy/engine/base.py","lineno":1674,"name":"_exec_driver_sql"},{"filename":"/home/airflow/.local/lib/python3.12/site-packages/sqlalchemy/engine/base.py","lineno":1953,"name":"_execute_context"},{"filename":"/home/airflow/.local/lib/python3.12/site-packages/sqlalchemy/engine/base.py","lineno":2138,"name":"_handle_dbapi_exception"},{"filename":"/home/airflow/.local/lib/python3.12/site-packages/sqlalchemy/util/compat.py","lineno":211,"name":"raise_"},{"filename":"/home/airflow/.local/lib/python3.12/site-packages/sqlalchemy/engine/base.py","lineno":1910,"name":"_execute_context"},{"filename":"/home/airflow/.local/lib/python3.12/site-packages/sqlalchemy/engine/default.py","lineno":736,"name":"do_execute"}],"is_group":false,"exceptions":[]}]}
{"timestamp":"2025-10-24T13:47:19.955344Z","level":"info","event":"Task instance in failure state","logger":"task.stdout"}
{"timestamp":"2025-10-24T13:47:19.966315Z","level":"info","event":"Task start","logger":"task.stdout"}
{"timestamp":"2025-10-24T13:47:19.998115Z","level":"info","event":"Task:<Task(PythonOperator): get_top_company>","logger":"task.stdout"}
{"timestamp":"2025-10-24T13:47:20.030078Z","level":"info","event":"Failure caused by dict is not a sequence","logger":"task.stdout"}
